<?xml version="1.1" encoding="utf-8"?>
<!-- =================================================================================== -->
<!-- Copyright 2024 PNDbotics, https://www.pndbotics.com/ -->
<!-- =================================================================================== -->
<!-- This file contains the description of the adam lite robot. -->
<robot name="adam_lite">
	<mujoco>
		<compiler meshdir="../meshes/" balanceinertia="true" discardvisual="false" />
	</mujoco>
	<!-- <link name="world" /> -->
	<link name="pelvis">
		<inertial>
			<origin xyz="-0.00034724 0 -0.00735759" rpy="0 0 0" />
			<mass value="10.3565" />
			<inertia ixx="0.06211826995" ixy="0.000001020115505" ixz="0.00007613076426" iyy="0.03451510004" iyz="-0.0000001757477311" izz="0.06877943001" />
		</inertial>
		<visual>
			<origin xyz="0 0 0" rpy="0 0 0" />
			<geometry>
				<mesh filename="../meshes/pelvis.STL" />
			</geometry>
			<material name="">
				<color rgba="1 1 1 1" />
			</material>
		</visual>
		<collision>
			<origin xyz="0.0 0.0 0" rpy="1.57 0 0" />
			<geometry>
				<cylinder length="0.2" radius="0.1" />
			</geometry>
		</collision>
	</link>
	<link name="left_hip_pitch_link">
		<inertial>
			<origin xyz="-0.0566022 0.0576144 -0.00077159" rpy="0 0 0" />
			<mass value="2.2338" />
			<inertia ixx="0.003621889254" ixy="0.001076088915" ixz="-0.00002179166295" iyy="0.004391391013" iyz="-0.00004444110953" izz="0.005154959733" />
		</inertial>
		<visual>
			<origin xyz="0 0 0" rpy="0 0 0" />
			<geometry>
				<mesh filename="../meshes/hipPitchLeft.STL" />
			</geometry>
			<material name="">
				<color rgba="1 1 1 1" />
			</material>
		</visual>
	</link>
	<joint name="left_hip_pitch_joint" type="revolute">
		<origin xyz="0 0.096192 -0.033241" rpy="-0.61087 0 0" />
		<parent link="pelvis" />
		<child link="left_hip_pitch_link" />
		<axis xyz="0 1 0" />
		<limit effort="230.0" lower="-2.164" upper="2.164" velocity="15.0" />
	</joint>
	<link name="left_hip_roll_link">
		<inertial>
			<origin xyz="0.0392416 0.00004107 -0.0103292" rpy="0 0 0" />
			<mass value="1.35108" />
			<inertia ixx="0.001222416004" ixy="0.000004629955863" ixz="0.00007103964906" iyy="0.001291158471" iyz="0.000007669784811" izz="0.001387535525" />
		</inertial>
		<visual>
			<origin xyz="0 0 0" rpy="0 0 0" />
			<geometry>
				<mesh filename="../meshes/hipRollLeft.STL" />
			</geometry>
			<material name="">
				<color rgba="1 1 1 1" />
			</material>
		</visual>
	</link>
	<joint name="left_hip_roll_joint" type="revolute">
		<origin xyz="-0.0255 0.069 0" rpy="0.61087 0 0" />
		<parent link="left_hip_pitch_link" />
		<child link="left_hip_roll_link" />
		<axis xyz="1 0 0" />
		<limit effort="180.0" lower="-0.733" upper="1.605" velocity="8.0" />
	</joint>
	<link name="left_hip_yaw_link">
		<inertial>
			<origin xyz="0.00244052 -0.00866423 -0.134336" rpy="0 0 0" />
			<mass value="6.43433" />
			<inertia ixx="0.05827183169" ixy="0.0002477447719" ixz="0.001357160561" iyy="0.06333936063" iyz="-0.005514697687" izz="0.01331160768" />
		</inertial>
		<visual>
			<origin xyz="0 0 0" rpy="0 0 0" />
			<geometry>
				<mesh filename="../meshes/thighLeft.STL" />
			</geometry>
			<material name="">
				<color rgba="1 1 1 1" />
			</material>
		</visual>
		<collision>
			<origin xyz="0 0 0" rpy="0 0 0" />
			<geometry>
				<mesh filename="../meshes/thighLeft.STL" />
			</geometry>
		</collision>
	</link>
	<joint name="left_hip_yaw_joint" type="revolute">
		<origin xyz="0.044 0 -0.0525" rpy="0 0 0" />
		<parent link="left_hip_roll_link" />
		<child link="left_hip_yaw_link" />
		<axis xyz="0 0 1" />
		<limit effort="105" lower="-0.785" upper="0.785" velocity="8.0" />
	</joint>
	<link name="left_knee_link">
		<inertial>
			<origin xyz="-0.00053135 0.00081959 -0.145381" rpy="0 0 0" />
			<mass value="2.25363" />
			<inertia ixx="0.0215135069" ixy="0.00001763179949" ixz="-0.0003226025966" iyy="0.02158743641" iyz="-0.00004329886697" izz="0.001369916683" />
		</inertial>
		<visual>
			<origin xyz="0 0 0" rpy="0 0 0" />
			<geometry>
				<mesh filename="../meshes/shinLeft.STL" />
			</geometry>
			<material name="">
				<color rgba="1 1 1 1" />
			</material>
		</visual>
		<collision>
			<origin xyz="0.0 0.0 -0.2" rpy="0 0 0" />
			<geometry>
				<box size="0.08 0.06 0.2" />
			</geometry>
		</collision>
	</link>
	<joint name="left_knee_joint" type="revolute">
		<origin xyz="0 -0.0355 -0.369" rpy="0 0 0" />
		<parent link="left_hip_yaw_link" />
		<child link="left_knee_link" />
		<axis xyz="0 1 0" />
		<limit effort="280.0" lower="0.052" upper="2.391" velocity="15.0" />
	</joint>
	<link name="left_ankle_pitch_link">
		<inertial>
			<origin xyz="0 0 0" rpy="0 0 0" />
			<mass value="0.0301423" />
			<inertia ixx="0.00000314" ixy="0" ixz="0" iyy="0.00000314" iyz="0" izz="0.00000204" />
		</inertial>
		<visual>
			<origin xyz="0 0 0" rpy="0 0 0" />
			<geometry>
				<mesh filename="../meshes/anklePitchLeft.STL" />
			</geometry>
			<material name="">
				<color rgba="1 1 1 1" />
			</material>
		</visual>
	</link>
	<joint name="left_ankle_pitch_joint" type="revolute">
		<origin xyz="0 0 -0.37" rpy="0 0 0" />
		<parent link="left_knee_link" />
		<child link="left_ankle_pitch_link" />
		<axis xyz="0 1 0" />
		<limit effort="80.0" lower="-1.0" upper="0.35" velocity="20.0" />
	</joint>
	<link name="left_ankle_roll_link">
		<inertial>
			<origin xyz="0.0374997 -0.00004016 -0.0419674" rpy="0 0 0" />
			<mass value="0.634796" />
			<inertia ixx="0.0004563602888" ixy="-0.00001602830597" ixz="0.0002010802065" iyy="0.002268940549" iyz="-0.000001800056332" izz="0.002313168162" />
		</inertial>
		<visual>
			<origin xyz="0 0 0" rpy="0 0 0" />
			<geometry>
				<mesh filename="../meshes/toeLeft.STL" />
			</geometry>
			<material name="">
				<color rgba="0.752941176470588 0.752941176470588 0.752941176470588 1" />
			</material>
		</visual>
		<collision name="toe_left1">
			<origin rpy="0 0 0" xyz="0.102 -0.045 -0.058" />
			<geometry>
				<sphere radius="0.005" />
			</geometry>
		</collision>
		<collision name="toe_left2">
			<origin rpy="0 0 0" xyz="0.162 0.0 -0.058" />
			<geometry>
				<sphere radius="0.005" />
			</geometry>
		</collision>
		<collision name="toe_left3">
			<origin rpy="0 0 0" xyz="0.102 0.045 -0.058" />
			<geometry>
				<sphere radius="0.005" />
			</geometry>
		</collision>
		<collision name="toe_left4">
			<origin rpy="0 0 0" xyz="0.03 -0.027 -0.058" />
			<geometry>
				<sphere radius="0.005" />
			</geometry>
		</collision>
		<collision name="toe_left5">
			<origin rpy="0 0 0" xyz="0.02 0.031 -0.058" />
			<geometry>
				<sphere radius="0.005" />
			</geometry>
		</collision>
		<collision name="toe_left6">
			<origin rpy="0 0 0" xyz="-0.055 0.03 -0.058" />
			<geometry>
				<sphere radius="0.005" />
			</geometry>
		</collision>
		<collision name="toe_left7">
			<origin rpy="0 0 0" xyz="-0.068 0.0 -0.058" />
			<geometry>
				<sphere radius="0.005" />
			</geometry>
		</collision>
		<collision name="toe_left8">
			<origin rpy="0 0 0" xyz="-0.055 -0.035 -0.058" />
			<geometry>
				<sphere radius="0.005" />
			</geometry>
		</collision>
	</link>
	<joint name="left_ankle_roll_joint" type="revolute">
		<origin xyz="0 0 0" rpy="0 0 0" />
		<parent link="left_ankle_pitch_link" />
		<child link="left_ankle_roll_link" />
		<axis xyz="1 0 0" />
		<limit effort="80.0" lower="-0.3491" upper="0.3491" velocity="20.0" />
	</joint>
	<link name="right_hip_pitch_link">
		<inertial>
			<origin xyz="-0.0566179 -0.0575934 -0.00078211" rpy="0 0 0" />
			<mass value="2.23477" />
			<inertia ixx="0.00362315229" ixy="-0.001074350742" ixz="-0.00002227924853" iyy="0.004394193637" iyz="0.00004505166332" izz="0.005158044073" />
		</inertial>
		<visual>
			<origin xyz="0 0 0" rpy="0 0 0" />
			<geometry>
				<mesh filename="../meshes/hipPitchRight.STL" />
			</geometry>
			<material name="">
				<color rgba="1 1 1 1" />
			</material>
		</visual>
	</link>
	<joint name="right_hip_pitch_joint" type="revolute">
		<origin xyz="0 -0.096192 -0.033241" rpy="0.61087 0 0" />
		<parent link="pelvis" />
		<child link="right_hip_pitch_link" />
		<axis xyz="0 1 0" />
		<limit effort="230.0" lower="-2.164" upper="2.164" velocity="15.0" />
	</joint>
	<link name="right_hip_roll_link">
		<inertial>
			<origin xyz="0.0392598 -0.00005814 -0.0103241" rpy="0 0 0" />
			<mass value="1.3517" />
			<inertia ixx="0.001222746823" ixy="-0.000005009987688" ixz="0.00007267074631" iyy="0.0012920847" iyz="-0.000008349523884" izz="0.001388608477" />
		</inertial>
		<visual>
			<origin xyz="0 0 0" rpy="0 0 0" />
			<geometry>
				<mesh filename="../meshes/hipRollRight.STL" />
			</geometry>
			<material name="">
				<color rgba="1 1 1 1" />
			</material>
		</visual>
	</link>
	<joint name="right_hip_roll_joint" type="revolute">
		<origin xyz="-0.0255 -0.069 0" rpy="-0.61087 0 0" />
		<parent link="right_hip_pitch_link" />
		<child link="right_hip_roll_link" />
		<axis xyz="1 0 0" />
		<limit effort="180.0" lower="-1.605" upper="0.733" velocity="8.0" />
	</joint>
	<link name="right_hip_yaw_link">
		<inertial>
			<origin xyz="0.00245598 0.00865064 -0.134332" rpy="0 0 0" />
			<mass value="6.43084" />
			<inertia ixx="0.05823195587" ixy="-0.0002448032423" ixz="0.00134041436" iyy="0.06331327942" iyz="0.005518582189" izz="0.01331916471" />
		</inertial>
		<visual>
			<origin xyz="0 0 0" rpy="0 0 0" />
			<geometry>
				<mesh filename="../meshes/thighRight.STL" />
			</geometry>
			<material name="">
				<color rgba="1 1 1 1" />
			</material>
		</visual>
		<collision>
			<origin xyz="0 0 0" rpy="0 0 0" />
			<geometry>
				<mesh filename="../meshes/thighRight.STL" />
			</geometry>
		</collision>
	</link>
	<joint name="right_hip_yaw_joint" type="revolute">
		<origin xyz="0.044 0 -0.0525" rpy="0 0 0" />
		<parent link="right_hip_roll_link" />
		<child link="right_hip_yaw_link" />
		<axis xyz="0 0 1" />
		<limit effort="105" lower="-0.785" upper="0.785" velocity="8.0" />
	</joint>
	<link name="right_knee_link">
		<inertial>
			<origin xyz="-0.00052844 -0.00082152 -0.145334" rpy="0 0 0" />
			<mass value="2.25459" />
			<inertia ixx="0.02149497919" ixy="-0.00001648739675" ixz="-0.0003214227826" iyy="0.02156788943" iyz="0.0000450185214" izz="0.001370051375" />
		</inertial>
		<visual>
			<origin xyz="0 0 0" rpy="0 0 0" />
			<geometry>
				<mesh filename="../meshes/shinRight.STL" />
			</geometry>
			<material name="">
				<color rgba="1 1 1 1" />
			</material>
		</visual>
		<collision>
			<origin xyz="0.0 0.0 -0.2" rpy="0 0 0" />
			<geometry>
				<box size="0.08 0.06 0.2" />
			</geometry>
		</collision>
	</link>
	<joint name="right_knee_joint" type="revolute">
		<origin xyz="0 0.0355 -0.369" rpy="0 0 0" />
		<parent link="right_hip_yaw_link" />
		<child link="right_knee_link" />
		<axis xyz="0 1 0" />
		<limit effort="280.0" lower="0.052" upper="2.391" velocity="15.0" />
	</joint>
	<link name="right_ankle_pitch_link">
		<inertial>
			<origin xyz="0 0 0" rpy="0 0 0" />
			<mass value="0.0301423" />
			<inertia ixx="0.00000314" ixy="0" ixz="0" iyy="0.00000314" iyz="0" izz="0.00000204" />
		</inertial>
		<visual>
			<origin xyz="0 0 0" rpy="0 0 0" />
			<geometry>
				<mesh filename="../meshes/anklePitchRight.STL" />
			</geometry>
			<material name="">
				<color rgba="0.752941176470588 0.752941176470588 0.752941176470588 1" />
			</material>
		</visual>
	</link>
	<joint name="right_ankle_pitch_joint" type="revolute">
		<origin xyz="0 0 -0.37" rpy="0 0 0" />
		<parent link="right_knee_link" />
		<child link="right_ankle_pitch_link" />
		<axis xyz="0 1 0" />
		<limit effort="80.0" lower="-1.0" upper="0.35" velocity="20.0" />
	</joint>
	<link name="right_ankle_roll_link">
		<inertial>
			<origin xyz="0.0375023 0.00004002 -0.0419671" rpy="0 0 0" />
			<mass value="0.634808" />
			<inertia ixx="0.0004563897647" ixy="0.00001602834002" ixz="0.0002010907482" iyy="0.00226894164" iyz="0.000001810344986" izz="0.002313174595" />
		</inertial>
		<visual>
			<origin xyz="0 0 0" rpy="0 0 0" />
			<geometry>
				<mesh filename="../meshes/toeRight.STL" />
			</geometry>
			<material name="">
				<color rgba="0.752941176470588 0.752941176470588 0.752941176470588 1" />
			</material>
		</visual>
		<collision name="toe_right1">
			<origin rpy="0 0 0" xyz="0.102 0.045 -0.058" />
			<geometry>
				<sphere radius="0.005" />
			</geometry>
		</collision>
		<collision name="toe_right2">
			<origin rpy="0 0 0" xyz="0.162 0.0 -0.058" />
			<geometry>
				<sphere radius="0.005" />
			</geometry>
		</collision>
		<collision name="toe_right3">
			<origin rpy="0 0 0" xyz="0.102 -0.045 -0.058" />
			<geometry>
				<sphere radius="0.005" />
			</geometry>
		</collision>
		<collision name="toe_right4">
			<origin rpy="0 0 0" xyz="0.03 0.027 -0.058" />
			<geometry>
				<sphere radius="0.005" />
			</geometry>
		</collision>
		<collision name="toe_right5">
			<origin rpy="0 0 0" xyz="0.02 -0.031 -0.058" />
			<geometry>
				<sphere radius="0.005" />
			</geometry>
		</collision>
		<collision name="toe_right6">
			<origin rpy="0 0 0" xyz="-0.055 -0.03 -0.058" />
			<geometry>
				<sphere radius="0.005" />
			</geometry>
		</collision>
		<collision name="toe_right7">
			<origin rpy="0 0 0" xyz="-0.068 0.0 -0.058" />
			<geometry>
				<sphere radius="0.005" />
			</geometry>
		</collision>
		<collision name="toe_right8">
			<origin rpy="0 0 0" xyz="-0.055 0.035 -0.058" />
			<geometry>
				<sphere radius="0.005" />
			</geometry>
		</collision>
	</link>
	<joint name="right_ankle_roll_joint" type="revolute">
		<origin xyz="0 0 0" rpy="0 0 0" />
		<parent link="right_ankle_pitch_link" />
		<child link="right_ankle_roll_link" />
		<axis xyz="1 0 0" />
		<limit effort="80.0" lower="-0.3491" upper="0.3491" velocity="20.0" />
	</joint>
	<link name="waist_roll_link">
		<inertial>
			<origin xyz="0.00093826 0.00093832 0.0399999" rpy="0 0 0" />
			<mass value="2.36268" />
			<inertia ixx="0.005430411799" ixy="0.000001712817746" ixz="0.00006791015632" iyy="0.005430442001" iyz="-0.00006793024775" izz="0.001849926199" />
		</inertial>
		<visual>
			<origin xyz="0 0 0" rpy="0 0 0" />
			<geometry>
				<mesh filename="../meshes/waistRoll.STL" />
			</geometry>
			<material name="">
				<color rgba="1 1 1 1" />
			</material>
		</visual>
	</link>
	<joint name="waist_roll_joint" type="revolute">
		<origin xyz="0 0 0.044" rpy="0 0 0" />
		<parent link="pelvis" />
		<child link="waist_roll_link" />
		<axis xyz="1 0 0" />
		<limit effort="150" lower="-0.279" upper="0.279" velocity="8.0" />
	</joint>
	<link name="waist_pitch_link">
		<inertial>
			<origin xyz="-0.00008401 0.00189362 0.0254832" rpy="0 0 0" />
			<mass value="0.563538" />
			<inertia ixx="0.001514701059" ixy="-0.00001036875743" ixz="-0.000004440167207" iyy="0.0006727904501" iyz="0.00001191967784" izz="0.001559072491" />
		</inertial>
		<visual>
			<origin xyz="0 0 0" rpy="0 0 0" />
			<geometry>
				<mesh filename="../meshes/waistPitch.STL" />
			</geometry>
			<material name="">
				<color rgba="1 1 1 1" />
			</material>
		</visual>
	</link>
	<joint name="waist_pitch_joint" type="revolute">
		<origin xyz="0 0 0.08" rpy="0 0 0" />
		<parent link="waist_roll_link" />
		<child link="waist_pitch_link" />
		<axis xyz="0 1 0" />
		<limit effort="150" lower="-0.663" upper="1.361" velocity="8.0" />
	</joint>
	<link name="torso_link">
		<inertial>
			<origin xyz="-0.00183601 0.00056583 0.166624" rpy="0 0 0" />
			<mass value="13.4634" />
			<inertia ixx="0.2113653854" ixy="0.0003651925274" ixz="-0.003228846193" iyy="0.1686513859" iyz="0.0002323707503" izz="0.07708492869" />
		</inertial>
		<visual>
			<origin xyz="0 0 0" rpy="0 0 0" />
			<geometry>
				<mesh filename="../meshes/torso.STL" />
			</geometry>
			<material name="">
				<color rgba="0.752941176470588 0.752941176470588 0.752941176470588 1" />
			</material>
		</visual>
		<collision>
			<origin xyz="0 0 0.15" rpy="0 0 0" />
			<geometry>
				<sphere radius="0.13" />
			</geometry>
		</collision>
	</link>
	<joint name="waist_yaw_joint" type="revolute">
		<origin xyz="0 0.0005 0.053" rpy="0 0 0" />
		<parent link="waist_pitch_link" />
		<child link="torso_link" />
		<axis xyz="0 0 1" />
		<limit effort="150" lower="-0.829" upper="0.829" velocity="8.0" />
	</joint>
	<link name="left_shoulder_pitch_link">
		<inertial>
			<origin xyz="0.00542694 0.0268987 0.00010792" rpy="0 0 0" />
			<mass value="0.216148" />
			<inertia ixx="0.0001904398566" ixy="-0.00002059018059" ixz="0.000001209993625" iyy="0.0003195498549" iyz="0.0000001600040021" izz="0.0003806402884" />
		</inertial>
		<visual>
			<origin xyz="0 0 0" rpy="0 0 0" />
			<geometry>
				<mesh filename="../meshes/shoulderPitchLeft.STL" />
			</geometry>
			<material name="">
				<color rgba="1 1 1 1" />
			</material>
		</visual>
	</link>
	<joint name="left_shoulder_pitch_joint" type="revolute">
		<origin xyz="0 0.16011 0.25742" rpy="0.34907 0 0" />
		<parent link="torso_link" />
		<child link="left_shoulder_pitch_link" />
		<axis xyz="0 1 0" />
		<limit effort="65.0" lower="-3.613" upper="2.042" velocity="8.0" />
	</joint>
	<link name="left_shoulder_roll_link">
		<inertial>
			<origin xyz="-0.0343733 0.00962154 -0.0154456" rpy="0 0 0" />
			<mass value="1.07882" />
			<inertia ixx="0.001670777464" ixy="0.000005539673081" ixz="-0.00001969034792" iyy="0.001404768246" iyz="0.0004355482573" izz="0.0009261182901" />
		</inertial>
		<visual>
			<origin xyz="0 0 0" rpy="0 0 0" />
			<geometry>
				<mesh filename="../meshes/shoulderRollLeft.STL" />
			</geometry>
			<material name="">
				<color rgba="1 1 1 1" />
			</material>
		</visual>
		<collision>
			<origin xyz="-0.03 0 0" rpy="0 1.5708 0" />
			<geometry>
				<cylinder length="0.1" radius="0.035" />
			</geometry>
		</collision>
	</link>
	<joint name="left_shoulder_roll_joint" type="revolute">
		<origin xyz="0.0335 0.0435 0" rpy="-0.34907 0 0" />
		<parent link="left_shoulder_pitch_link" />
		<child link="left_shoulder_roll_link" />
		<axis xyz="1 0 0" />
		<limit effort="65.0" lower="-0.628" upper="2.793" velocity="8.0" />
	</joint>
	<link name="left_shoulder_yaw_link">
		<inertial>
			<origin xyz="-0.00051421 -0.00044442 -0.0619328" rpy="0 0 0" />
			<mass value="0.90142" />
			<inertia ixx="0.003285576139" ixy="-0.0000002000421971" ixz="-0.00004742999673" iyy="0.003172262887" iyz="-0.00004945004175" izz="0.0005758899739" />
		</inertial>
		<visual>
			<origin xyz="0 0 0" rpy="0 0 0" />
			<geometry>
				<mesh filename="../meshes/shoulderYawLeft.STL" />
			</geometry>
			<material name="">
				<color rgba="1 1 1 1" />
			</material>
		</visual>
		<collision>
			<origin xyz="0 0. -0.08" rpy="0 0 0" />
			<geometry>
				<cylinder length="0.15" radius="0.038" />
			</geometry>
		</collision>
	</link>
	<joint name="left_shoulder_yaw_joint" type="revolute">
		<origin xyz="-0.0335 0.034 -0.0585" rpy="0 0 0" />
		<parent link="left_shoulder_roll_link" />
		<child link="left_shoulder_yaw_link" />
		<axis xyz="0 0 1" />
		<limit effort="65.0" lower="-2.583" upper="2.583" velocity="8.0" />
	</joint>
	<link name="left_elbow_link">
		<inertial>
			<origin xyz="-0.02164423 0.02776208 -0.04469642" rpy="0 0 0" />
			<mass value="0.85400000" />
			<inertia ixx="0.00072987" ixy="-0.00001380" ixz="0.00015644" iyy="0.00080410" iyz="-0.00002763" izz="0.00047565" />
		</inertial>
		<visual>
			<origin xyz="0 0 0" rpy="0 0 0" />
			<geometry>
				<mesh filename="../meshes/elbowLeft.STL" />
			</geometry>
			<material name="">
				<color rgba="1 1 1 1" />
			</material>
		</visual>
		<collision>
			<origin xyz="0 0 0" rpy="0 0 0" />
			<geometry>
				<mesh filename="../meshes/elbowLeft.STL" />
			</geometry>
		</collision>
	</link>
	<joint name="left_elbow_joint" type="revolute">
		<origin xyz="0 -0.0285 -0.20415" rpy="0 0 0" />
		<parent link="left_shoulder_yaw_link" />
		<child link="left_elbow_link" />
		<axis xyz="0 1 0" />
		<limit effort="30.0" lower="-2.496" upper="0.209" velocity="8.0" />
	</joint>
	<link name="left_wrist_yaw_link">
		<inertial>
			<origin xyz="0.00001826 -0.00013856 -0.15608944" rpy="0 0 0" />
			<mass value="0.73460000" />
			<inertia ixx="0.00772306" ixy="0.00000000" ixz="0.00000198" iyy="0.00772311" iyz="0.00001414" izz="0.00029992" />
		</inertial>
		<visual>
			<origin xyz="0 0 0" rpy="0 0 0" />
			<geometry>
				<mesh filename="../meshes/wristYawLeft.STL" />
			</geometry>
			<material name="">
				<color rgba="1 1 1 1" />
			</material>
		</visual>
		<collision>
			<origin xyz="0 0 0" rpy="0 0 0" />
			<geometry>
				<mesh filename="../meshes/wristYawLeft.STL" />
			</geometry>
		</collision>
	</link>
	<joint name="left_wrist_yaw_joint" type="fixed">
		<origin xyz="-0.025 0.0285 -0.0729" rpy="0 0 0" />
		<parent link="left_elbow_link" />
		<child link="left_wrist_yaw_link" />
		<axis xyz="0 0 1" />
		<limit effort="6.4" velocity="4.9218" />
	</joint>
	<link name="right_shoulder_pitch_link">
		<inertial>
			<origin xyz="0.00536737 -0.0269397 0.00010693" rpy="0 0 0" />
			<mass value="0.216487" />
			<inertia ixx="0.0001906499477" ixy="0.00002021012301" ixz="0.000001210114293" iyy="0.0003200397488" iyz="-0.0000001600189813" izz="0.0003813303035" />
		</inertial>
		<visual>
			<origin xyz="0 0 0" rpy="0 0 0" />
			<geometry>
				<mesh filename="../meshes/shoulderPitchRight.STL" />
			</geometry>
			<material name="">
				<color rgba="1 1 1 1" />
			</material>
		</visual>
	</link>
	<joint name="right_shoulder_pitch_joint" type="revolute">
		<origin xyz="0 -0.16011 0.25742" rpy="-0.34907 0 0" />
		<parent link="torso_link" />
		<child link="right_shoulder_pitch_link" />
		<axis xyz="0 1 0" />
		<limit effort="65.0" lower="-3.613" upper="2.042" velocity="8.0" />
	</joint>
	<link name="right_shoulder_roll_link">
		<inertial>
			<origin xyz="-0.0342995 -0.00987424 -0.0157184" rpy="0 0 0" />
			<mass value="1.08875" />
			<inertia ixx="0.001696507557" ixy="-0.000001650518802" ixz="-0.00001991975361" iyy="0.001422359449" iyz="-0.0004428388597" izz="0.0009388889941" />
		</inertial>
		<visual>
			<origin xyz="0 0 0" rpy="0 0 0" />
			<geometry>
				<mesh filename="../meshes/shoulderRollRight.STL" />
			</geometry>
			<material name="">
				<color rgba="1 1 1 1" />
			</material>
		</visual>
		<collision>
			<origin xyz="-0.03 0 0" rpy="0 1.5708 0" />
			<geometry>
				<cylinder length="0.1" radius="0.035" />
			</geometry>
		</collision>
	</link>
	<joint name="right_shoulder_roll_joint" type="revolute">
		<origin xyz="0.0335 -0.0435 0" rpy="0.34907 0 0" />
		<parent link="right_shoulder_pitch_link" />
		<child link="right_shoulder_roll_link" />
		<axis xyz="1 0 0" />
		<limit effort="65.0" lower="-2.793" upper="0.628" velocity="8.0" />
	</joint>
	<link name="right_shoulder_yaw_link">
		<inertial>
			<origin xyz="-0.00051403 0.00046316 -0.0619299" rpy="0 0 0" />
			<mass value="0.901393" />
			<inertia ixx="0.003285269124" ixy="-0.0000002799366739" ixz="-0.00004741019827" iyy="0.003171984931" iyz="0.00004934007548" izz="0.0005758399452" />
		</inertial>
		<visual>
			<origin xyz="0 0 0" rpy="0 0 0" />
			<geometry>
				<mesh filename="../meshes/shoulderYawRight.STL" />
			</geometry>
			<material name="">
				<color rgba="1 1 1 1" />
			</material>
		</visual>
		<collision>
			<origin xyz="0 0. -0.08" rpy="0 0 0" />
			<geometry>
				<cylinder length="0.15" radius="0.038" />
			</geometry>
		</collision>
	</link>
	<joint name="right_shoulder_yaw_joint" type="revolute">
		<origin xyz="-0.0335 -0.034 -0.0585" rpy="0 0 0" />
		<parent link="right_shoulder_roll_link" />
		<child link="right_shoulder_yaw_link" />
		<axis xyz="0 0 1" />
		<limit effort="65.0" lower="-2.583" upper="2.583" velocity="8.0" />
	</joint>
	<link name="right_elbow_link">
		<inertial>
			<origin xyz="-0.01212328 -0.02629569 -0.02658404" rpy="0 0 0" />
			<mass value="0.85400000" />
			<inertia ixx="0.00099546" ixy="0.00002241" ixz="0.00027937" iyy="0.00111379" iyz="0.00004820" izz="0.00053993" />
		</inertial>
		<visual>
			<origin xyz="0 0 0" rpy="0 0 0" />
			<geometry>
				<mesh filename="../meshes/elbowRight.STL" />
			</geometry>
			<material name="">
				<color rgba="1 1 1 1" />
			</material>
		</visual>
		<collision>
			<origin xyz="0 0 0" rpy="0 0 0" />
			<geometry>
				<mesh filename="../meshes/elbowRight.STL" />
			</geometry>
		</collision>
	</link>
	<joint name="right_elbow_joint" type="revolute">
		<origin xyz="0 0.0285 -0.20415" rpy="0 0 0" />
		<parent link="right_shoulder_yaw_link" />
		<child link="right_elbow_link" />
		<axis xyz="0 1 0" />
		<limit effort="30.0" lower="-2.496" upper="0.209" velocity="8.0" />
	</joint>
	<link name="right_wrist_yaw_link">
		<inertial>
			<origin xyz="0.00001640 0.00018166 -0.17795217" rpy="0 0 0" />
			<mass value="0.73460000" />
			<inertia ixx="0.00787989" ixy="0.00000000" ixz="0.00000202" iyy="0.00788003" iyz="-0.00001563" izz="0.00031258" />
		</inertial>
		<visual>
			<origin xyz="0 0 0" rpy="0 0 0" />
			<geometry>
				<mesh filename="../meshes/wristYawRight.STL" />
			</geometry>
			<material name="">
				<color rgba="1 1 1 1" />
			</material>
		</visual>
		<collision>
			<origin xyz="0 0 0" rpy="0 0 0" />
			<geometry>
				<mesh filename="../meshes/wristYawRight.STL" />
			</geometry>
		</collision>
	</link>
	<joint name="right_wrist_yaw_joint" type="fixed">
		<origin xyz="-0.025 -0.0285 -0.0729" rpy="0 0 0" />
		<parent link="right_elbow_link" />
		<child link="right_wrist_yaw_link" />
		<axis xyz="0 0 1" />
	</joint>
	<link name="EE_L_hand"/>
	<link name="EE_R_hand"/>
	<link name="EE_L_foot"/>
	<link name="EE_R_foot"/>

	<joint name="L_hand_symbol" type="fixed" dont_collapse="true">
	  <parent link="left_wrist_yaw_link"/>
	  <child link="EE_L_hand"/>
	  <origin xyz="0.0 0.0 -0.28" rpy="0.0 0.0 0.0"/>
	</joint>


	<joint name="R_hand_symbol" type="fixed" dont_collapse="true">
	  <parent link="right_wrist_yaw_link"/>
	  <child link="EE_R_hand"/>
	  <origin xyz="0.0 0.0 -0.28" rpy="0.0 0.0 0.0"/>
	</joint>

	<joint name="L_foot_symbol" type="fixed" dont_collapse="true">
	  <parent link="left_ankle_roll_link"/>
	  <child link="EE_L_foot"/>
	  <origin xyz="0.0 0.0 0.0" rpy="0.0 0.0 0.0"/>
	</joint>

	<joint name="R_foot_symbol" type="fixed" dont_collapse="true">
	  <parent link="right_ankle_roll_link"/>
	  <child link="EE_R_foot"/>
	  <origin xyz="0.0 0.0 0.0" rpy="0.0 0.0 0.0"/>
	</joint>


	  <link name="L_foot_end" />
	  <link name="L_foot_tip" />
	  <link name="R_foot_end" />
	  <link name="R_foot_tip" />

	  <joint name="L_foot_tip_joint" type="fixed">
	    <origin rpy="3.14159 0.00000 0.00000" xyz="0.1355 0.00000 -0.06500" />
	    <parent link="EE_L_foot" />
	    <child link="L_foot_tip" />
	  </joint>
	  <joint name="L_foot_end_joint" type="fixed">
	    <origin rpy="3.14159 0.00000 0.00000" xyz="-0.055  0.00000 -0.06500" />
	    <parent link="EE_L_foot" />
	    <child link="L_foot_end" />
	  </joint>
	  <joint name="R_foot_end_joint" type="fixed">
	    <origin rpy="3.14159 0.00000 0.00000" xyz="-0.055  0.00000 -0.06500" />
	    <parent link="EE_R_foot" />
	    <child link="R_foot_end" />
	  </joint>
	  <joint name="R_foot_tip_joint" type="fixed">
	    <origin rpy="3.14159 0.00000 0.00000" xyz="0.1355 0.00000 -0.06500" />
	    <parent link="EE_R_foot" />
	    <child link="R_foot_tip" />
	  </joint>

	  <link name="L_foot_end_real" />
	  <link name="R_foot_end_real" />

	  <joint name="L_foot_end_real_joint" type="fixed">
	    <origin rpy="3.14159 0.00000 0.00000" xyz="-0.075  0.00000 -0.06500" />
	    <parent link="EE_L_foot" />
	    <child link="L_foot_end_real" />
	  </joint>

	  <joint name="R_foot_end_real_joint" type="fixed">
	    <origin rpy="3.14159 0.00000 0.00000" xyz="-0.075  0.00000 -0.06500" />
	    <parent link="EE_R_foot" />
	    <child link="R_foot_end_real" />
	  </joint>
</robot>
